2022-03-06 00:36:31,197 - __main__ - INFO - 开始获取[elementData.xlsx]的[elementsInfo]表
2022-03-06 00:36:31,210 - __main__ - INFO - 开始获取[elementData.xlsx]的[userIdPw]表
2022-03-06 00:36:31,214 - __main__ - ERROR - 获取工作表[userIdPw]失败
Traceback (most recent call last):
  File "D:\Software\python\Anaconda\lib\site-packages\xlrd\book.py", line 474, in sheet_by_name
    sheetx = self._sheet_names.index(sheet_name)
ValueError: 'userIdPw' is not in list

During handling of the above exception, another exception occurred:

Traceback (most recent call last):
  File "D:/Software/PycharmProjects/sccProjects/config/doExcel.py", line 18, in __init__
    self.sheetName = self.workBook.sheet_by_name(sheetName) #获取名字为sheetName的工作表
  File "D:\Software\python\Anaconda\lib\site-packages\xlrd\book.py", line 476, in sheet_by_name
    raise XLRDError('No sheet named <%r>' % sheet_name)
xlrd.biffh.XLRDError: No sheet named <'userIdPw'>
2022-03-06 00:36:53,568 - config.doExcel - INFO - 开始获取[elementData.xlsx]的[elementsInfo]表
2022-03-06 00:36:53,584 - config.doExcel - INFO - 开始获取[elementDate.xlsx]的[loginData]表
2022-03-06 00:36:53,584 - config.doExcel - ERROR - 获取工作表[loginData]失败
Traceback (most recent call last):
  File "D:\Software\PycharmProjects\sccProjects\config\doExcel.py", line 17, in __init__
    self.workBook = xlrd.open_workbook(self.dataFile)
  File "D:\Software\python\Anaconda\lib\site-packages\xlrd\__init__.py", line 111, in open_workbook
    with open(filename, "rb") as f:
FileNotFoundError: [Errno 2] No such file or directory: 'D:\\Software\\PycharmProjects\\sccProjects\\testData\\elementDate.xlsx'
