2022-03-06 10:46:01,904 - pageObject.basePage - ERROR - basePage -39 - Message: unknown error: net::ERR_CONNECTION_REFUSED
  (Session info: chrome=99.0.4844.51)
Traceback (most recent call last):
  File "D:\Software\PycharmProjects\sccProjects\pageObject\basePage.py", line 34, in _open
    self.driver.get(url)
  File "D:\Software\python\Anaconda\lib\site-packages\selenium\webdriver\remote\webdriver.py", line 333, in get
    self.execute(Command.GET, {'url': url})
  File "D:\Software\python\Anaconda\lib\site-packages\selenium\webdriver\remote\webdriver.py", line 321, in execute
    self.error_handler.check_response(response)
  File "D:\Software\python\Anaconda\lib\site-packages\selenium\webdriver\remote\errorhandler.py", line 242, in check_response
    raise exception_class(message, screen, stacktrace)
selenium.common.exceptions.WebDriverException: Message: unknown error: net::ERR_CONNECTION_REFUSED
  (Session info: chrome=99.0.4844.51)

2022-03-06 10:46:04,179 - pageObject.basePage - ERROR - basePage -39 - Message: unknown error: cannot determine loading status
from disconnected: received Inspector.detached event
  (Session info: chrome=99.0.4844.51)
Traceback (most recent call last):
  File "D:\Software\PycharmProjects\sccProjects\pageObject\basePage.py", line 34, in _open
    self.driver.get(url)
  File "D:\Software\python\Anaconda\lib\site-packages\selenium\webdriver\remote\webdriver.py", line 333, in get
    self.execute(Command.GET, {'url': url})
  File "D:\Software\python\Anaconda\lib\site-packages\selenium\webdriver\remote\webdriver.py", line 321, in execute
    self.error_handler.check_response(response)
  File "D:\Software\python\Anaconda\lib\site-packages\selenium\webdriver\remote\errorhandler.py", line 242, in check_response
    raise exception_class(message, screen, stacktrace)
selenium.common.exceptions.WebDriverException: Message: unknown error: cannot determine loading status
from disconnected: received Inspector.detached event
  (Session info: chrome=99.0.4844.51)

