2022-03-06 11:14:23,858 - testLogin - ERROR - testLogin -44 - 登录测试用例：%s 成功进入首页，但未成功登录
Traceback (most recent call last):
  File "D:\Software\PycharmProjects\sccProjects\testCase\testLogin.py", line 40, in test_login
    result = self.assertIn(userData["expected"], message)
  File "D:\Software\python\Anaconda\lib\unittest\case.py", line 1119, in assertIn
    self.fail(self._formatMessage(msg, standardMsg))
  File "D:\Software\python\Anaconda\lib\unittest\case.py", line 693, in fail
    raise self.failureException(msg)
AssertionError: '个人信息 ' not found in '个人信息(Information)'
2022-03-06 11:14:23,905 - pageObject.basePage - ERROR - basePage -272 - 未能保存失败截图
Traceback (most recent call last):
  File "D:\Software\PycharmProjects\sccProjects\testCase\testLogin.py", line 40, in test_login
    result = self.assertIn(userData["expected"], message)
  File "D:\Software\python\Anaconda\lib\unittest\case.py", line 1119, in assertIn
    self.fail(self._formatMessage(msg, standardMsg))
  File "D:\Software\python\Anaconda\lib\unittest\case.py", line 693, in fail
    raise self.failureException(msg)
AssertionError: '个人信息 ' not found in '个人信息(Information)'

During handling of the above exception, another exception occurred:

Traceback (most recent call last):
  File "D:\Software\PycharmProjects\sccProjects\pageObject\basePage.py", line 268, in saveScreenShot
    self.driver.save_screenshot(os.path.join(conf.failImagePath,filename))
AttributeError: 'ConfigParser' object has no attribute 'failImagePath'
2022-03-06 11:14:35,640 - pageObject.basePage - ERROR - basePage -63 - 元素定位超时：('id', 'username')
Traceback (most recent call last):
  File "D:\Software\PycharmProjects\sccProjects\pageObject\basePage.py", line 61, in findElement
    WebDriverWait(self.driver,10).until(EC.visibility_of_element_located(loc))
  File "D:\Software\python\Anaconda\lib\site-packages\selenium\webdriver\support\wait.py", line 80, in until
    raise TimeoutException(message, screen, stacktrace)
selenium.common.exceptions.TimeoutException: Message: 

